Workbook

Sheet game_parameters
A1: 編號 | B1: 變動 | C1: 系統分類 | D1: 名稱 | E1: 參數化公式 | F1: 中文說明 | G1: 參數a | H1: 參數b | I1: 參數c | J1: 參數d | K1: 參數e | L1: 參數f | M1: 參數g | N1: 參數h | O1: 參數i | P1: 參數j | Q1: 參數k | R1: 參數l
A2: =計算表!A2 -> 1 | B2: =計算表!B2 -> 0 | C2: =計算表!C2 -> 0-遊戲預設 | D2: =計算表!D2 -> 開場金幣 | E2: =計算表!E2 -> a | F2: =計算表!F2 -> 新遊戲與重新開局時給予的金幣數量。 | G2: =計算表!G2 -> 50000 | H2: =計算表!H2 -> 0 | ... R2: =計算表!R2 -> 0
A3: =計算表!A3 -> 2 | B3: =計算表!B3 -> 0 | C3: =計算表!C3 -> 0-遊戲預設 | D3: =計算表!D3 -> 開場裝備碎片 | E3: =計算表!E3 -> a | F3: =計算表!F3 -> 新遊戲與重新開局時給予的裝備碎片數量。 | G3: =計算表!G3 -> 500 | H3: =計算表!H3 -> 0 | ... R3: =計算表!R3 -> 0
A4: =計算表!A4 -> 3 | B4: =計算表!B4 -> 0 | C4: =計算表!C4 -> 0-遊戲預設 | D4: =計算表!D4 -> 開場附魔精華 | E4: =計算表!E4 -> a | F4: =計算表!F4 -> 新遊戲與重新開局時給予的附魔精華數量。 | G4: =計算表!G4 -> 100 | H4: =計算表!H4 -> 0 | ... R4: =計算表!R4 -> 0
A5: =計算表!A5 -> 4 | B5: =計算表!B5 -> 0 | C5: =計算表!C5 -> 10-離線 | D5: =計算表!D5 -> 有效離線時間 | E5: =計算表!E5 -> min(實際離線秒數, a 小時) | F5: =計算表!F5 -> 1 分鐘內不計。 | G5: =計算表!G5 -> 24 | H5: =計算表!H5 -> 0 | ... R5: =計算表!R5 -> 0
A6: =計算表!A6 -> 5 | B6: =計算表!B6 -> 0 | C6: =計算表!C6 -> 10-離線 | D6: =計算表!D6 -> 計算等級 | E6: =計算表!E6 -> 捨去((目前地圖最高階段 × c - a) ÷ b) × b（下限 1） | F6: =計算表!F6 -> a=等級扣減；b=取整單位；c=關卡比例；以此等級的當前場景菁英怪計算離線收益。 | G6: =計算表!G6 -> 10 | H6: =計算表!H6 -> 10 | ... R6: =計算表!R6 -> 0
A7: =計算表!A7 -> 6 | B7: =計算表!B7 -> 0 | C7: =計算表!C7 -> 10-離線 | D7: =計算表!D7 -> 擊殺速率 | E7: =計算表!E7 -> 每 a 秒擊殺 1 隻菁英怪 | F7: =計算表!F7 -> a=擊殺間隔秒數；擊殺數 = ⌊有效離線秒數 ÷ a⌋，每隻菁英怪及其掉落單獨擲骰。 | G7: =計算表!G7 -> 10 | H7: =計算表!H7 -> 0 | ... R7: =計算表!R7 -> 0
A8: =計算表!A8 -> 7 | B8: =計算表!B8 -> 0 | C8: =計算表!C8 -> 10-離線 | D8: =計算表!D8 -> 怪物種類 | E8: =計算表!E8 -> a＝1 時使用菁英怪；a＝0 時使用普通怪 | F8: =計算表!F8 -> 離線收益的怪物種類；菁英怪會套用菁英經驗與掉落倍率。 | G8: =計算表!G8 -> 1 | H8: =計算表!H8 -> 0 | ... R8: =計算表!R8 -> 0
A9: =計算表!A9 -> 8 | B9: =計算表!B9 -> 0 | C9: =計算表!C9 -> 1-成長經驗 | D9: =計算表!D9 -> 升級所需經驗 | E9: =計算表!E9 -> (a×等級^b+c)×轉生經驗倍率+轉生經驗基礎增加值 | F9: =計算表!F9 -> 升到下一級所需經驗；a=係數 b=次方 c=常數 d=等級上限。轉生經驗倍率見「轉生對照表」 | G9: =計算表!G9 -> 20 | H9: =計算表!H9 -> 3 | ... R9: =計算表!R9 -> 0
A10: =計算表!A10 -> 9 | B10: =計算表!B10 -> 0 | C10: =計算表!C10 -> 1-成長經驗 | D10: =計算表!D10 -> 等級基礎四維 | E10: =計算表!E10 -> a+(等級-1)×b | F10: =計算表!F10 -> 力/敏/智/耐四項相同，每升 1 級各 +b。a=初始值 b=每級成長。 | G10: =計算表!G10 -> 5 | H10: =計算表!H10 -> 2 | ... R10: =計算表!R10 -> 0
A11: =計算表!A11 -> 10 | B11: =計算表!B11 -> 0 | C11: =計算表!C11 -> 1-成長經驗 | D11: =計算表!D11 -> 技能點總預算 | E11: =計算表!E11 -> 基礎a + 技能熟練度等級 + 潛力天賦加成 | F11: 2026-07-30 改制：技能點不再隨角色升級發放，改由技能熟練度提供（每級 1 點）；目前只用於潛力技能。a=基礎點數；b 停用；c=舊制上限常數（保留相容）。 | G11: =計算表!G11 -> 3 | H11: =計算表!H11 -> 1 | I11: =計算表!I11 -> 10000 | J11: =計算表!J11 -> 0 | K11: =計算表!K11 -> 0 | L11: =計算表!L11 -> 0 | M11: =計算表!M11 -> 0 | N11: =計算表!N11 -> 0 | ... R11: =計算表!R11 -> 0
A12: =計算表!A12 -> 11 | B12: =計算表!B12 -> 0 | C12: =計算表!C12 -> 1-成長經驗 | D12: =計算表!D12 -> 技能裝載欄 | E12: =計算表!E12 -> clamp(⌊等級/a⌋, b, c) | F12: =計算表!F12 -> 每 a 級 +1 格，最少 b、最多 c。 | G12: =計算表!G12 -> 50 | H12: =計算表!H12 -> 4 | ... R12: =計算表!R12 -> 0
A13: =計算表!A13 -> 12 | B13: =計算表!B13 -> 0 | C13: =計算表!C13 -> 1-成長經驗 | D13: =計算表!D13 -> 可轉生等級 / 最高轉生 | E13: =計算表!E13 -> 達到a級可轉生；最高b轉 | F13: =計算表!F13 -> a=可轉生等級 b=最高轉生次數。 | G13: =計算表!G13 -> 1000 | H13: =計算表!H13 -> 20 | ... R13: =計算表!R13 -> 0
A14: =計算表!A14 -> 13 | B14: =計算表!B14 -> 0 | C14: =計算表!C14 -> 1-成長經驗 | D14: =計算表!D14 -> 神鑄系統解鎖等級 | E14: =計算表!E14 -> b 轉達到a級開放 | F14: =計算表!F14 -> 解鎖後永久保留，轉生不關閉。a=解鎖等級 b=解鎖轉生等級，必需兩個條件都滿足才解鎖 | G14: =計算表!G14 -> 1 | H14: =計算表!H14 -> 1 | ... R14: =計算表!R14 -> 0
A15: =計算表!A15 -> 14 | B15: =計算表!B15 -> 0 | C15: =計算表!C15 -> 1-成長經驗 | D15: =計算表!D15 -> 技能熟練度經驗需求 | E15: =計算表!E15 -> a×熟練度等級^b + c | F15: =計算表!F15 -> 技能熟練度升 1 級所需經驗（沿用玩家升級公式未轉生版；L=目前熟練度等級）。 | G15: =計算表!G15 -> 30 | H15: =計算表!H15 -> 3 | ... R15: =計算表!R15 -> 0
A16: =計算表!A16 -> 15 | B16: =計算表!B16 -> 0 | C16: =計算表!C16 -> 1-成長經驗 | D16: =計算表!D16 -> 技能熟練度 | E16: =計算表!E16 -> 上限 a 級；擊殺技能經驗 = 怪物經驗 × b% | F16: =計算表!F16 -> 打怪（野外/高塔/離線）獲得技能經驗；每升 1 級 +1 技能點。初始 0 級。 | G16: =計算表!G16 -> 1000 | H16: =計算表!H16 -> 90 | ... R16: =計算表!R16 -> 0
A17: =計算表!A17 -> 16 | B17: =計算表!B17 -> 0 | C17: =計算表!C17 -> 1-轉生對照表 | D17: =計算表!D17 -> 轉生 0 次 | E17: =計算表!E17 -> （查表） | F17: a=生命與四維最終倍率 b=升級經驗倍率 c=升級經驗基礎增加值 d=階級名稱 e=潛力技能等級上限（查表）。 f=已停用（舊融合技上限增加值，2026-09-29 移除）。 | G17: =計算表!G17 -> 1 | H17: =計算表!H17 -> 10^0 | I17: =計算表!I17 -> 0 | J17: =計算表!J17 -> 冒險者 | K17: =計算表!K17 -> 10 | L17: =計算表!L17 -> 0 | M17: =計算表!M17 -> 0 | N17: =計算表!N17 -> 0 | ... R17: =計算表!R17 -> 0
A18: =計算表!A18 -> 17 | B18: =計算表!B18 -> 0 | C18: =計算表!C18 -> 1-轉生對照表 | D18: =計算表!D18 -> 轉生 1 次 | E18: =計算表!E18 -> （查表） | F18: a=生命與四維最終倍率 b=升級經驗倍率 c=升級經驗基礎增加值 d=階級名稱 e=潛力技能等級上限（查表）。 f=已停用（舊融合技上限增加值，2026-09-29 移除）。 | G18: =計算表!G18 -> 1.5 | H18: =計算表!H18 -> 10^1 | I18: =計算表!I18 -> 500000 | J18: =計算表!J18 -> 勇者 | K18: =計算表!K18 -> 12 | L18: =計算表!L18 -> 0 | M18: =計算表!M18 -> 0 | N18: =計算表!N18 -> 0 | ... R18: =計算表!R18 -> 0
A19: =計算表!A19 -> 18 | B19: =計算表!B19 -> 0 | C19: =計算表!C19 -> 1-轉生對照表 | D19: =計算表!D19 -> 轉生 2 次 | E19: =計算表!E19 -> （查表） | F19: a=生命與四維最終倍率 b=升級經驗倍率 c=升級經驗基礎增加值 d=階級名稱 e=潛力技能等級上限（查表）。 f=已停用（舊融合技上限增加值，2026-09-29 移除）。 | G19: =計算表!G19 -> 2.5 | H19: =計算表!H19 -> 10^2 | I19: =計算表!I19 -> 1500000 | J19: =計算表!J19 -> 大劍師 | K19: =計算表!K19 -> 14 | L19: =計算表!L19 -> 0 | M19: =計算表!M19 -> 0 | N19: =計算表!N19 -> 0 | ... R19: =計算表!R19 -> 0
A20: =計算表!A20 -> 19 | B20: =計算表!B20 -> 0 | C20: =計算表!C20 -> 1-轉生對照表 | D20: =計算表!D20 -> 轉生 3 次 | E20: =計算表!E20 -> （查表） | F20: a=生命與四維最終倍率 b=升級經驗倍率 c=升級經驗基礎增加值 d=階級名稱 e=潛力技能等級上限（查表）。 f=已停用（舊融合技上限增加值，2026-09-29 移除）。 | G20: =計算表!G20 -> 3.5 | H20: =計算表!H20 -> 10^3 | I20: =計算表!I20 -> 3000000 | J20: =計算表!J20 -> 破世者 | K20: =計算表!K20 -> 16 | L20: =計算表!L20 -> 0 | M20: =計算表!M20 -> 0 | N20: =計算表!N20 -> 0 | ... R20: =計算表!R20 -> 0
A21: =計算表!A21 -> 20 | B21: =計算表!B21 -> 0 | C21: =計算表!C21 -> 1-轉生對照表 | D21: =計算表!D21 -> 轉生 4 次 | E21: =計算表!E21 -> （查表） | F21: a=生命與四維最終倍率 b=升級經驗倍率 c=升級經驗基礎增加值 d=階級名稱 e=潛力技能等級上限（查表）。 f=已停用（舊融合技上限增加值，2026-09-29 移除）。 | G21: =計算表!G21 -> 5 | H21: =計算表!H21 -> 10^4 | I21: =計算表!I21 -> 6000000 | J21: =計算表!J21 -> 不朽者 | K21: =計算表!K21 -> 18 | L21: =計算表!L21 -> 0 | M21: =計算表!M21 -> 0 | N21: =計算表!N21 -> 0 | ... R21: =計算表!R21 -> 0
A22: =計算表!A22 -> 21 | B22: =計算表!B22 -> 0 | C22: =計算表!C22 -> 1-轉生對照表 | D22: =計算表!D22 -> 轉生 5 次 | E22: =計算表!E22 -> （查表） | F22: a=生命與四維最終倍率 b=升級經驗倍率 c=升級經驗基礎增加值 d=階級名稱 e=潛力技能等級上限（查表）。 f=已停用（舊融合技上限增加值，2026-09-29 移除）。 | G22: =計算表!G22 -> 7 | H22: =計算表!H22 -> 10^5 | I22: =計算表!I22 -> 12000000 | J22: =計算表!J22 -> 王者 | K22: =計算表!K22 -> 20 | L22: =計算表!L22 -> 0 | M22: =計算表!M22 -> 0 | N22: =計算表!N22 -> 0 | ... R22: =計算表!R22 -> 0
A23: =計算表!A23 -> 22 | B23: =計算表!B23 -> 0 | C23: =計算表!C23 -> 1-轉生對照表 | D23: =計算表!D23 -> 轉生 6 次 | E23: =計算表!E23 -> （查表） | F23: a=生命與四維最終倍率 b=升級經驗倍率 c=升級經驗基礎增加值 d=階級名稱 e=潛力技能等級上限（查表）。 f=已停用（舊融合技上限增加值，2026-09-29 移除）。 | G23: =計算表!G23 -> 10 | H23: =計算表!H23 -> 10^6 | I23: =計算表!I23 -> 24000000 | J23: =計算表!J23 -> 大主宰 | K23: =計算表!K23 -> 22 | L23: =計算表!L23 -> 0 | M23: =計算表!M23 -> 0 | N23: =計算表!N23 -> 0 | ... R23: =計算表!R23 -> 0
A24: =計算表!A24 -> 23 | B24: =計算表!B24 -> 0 | C24: =計算表!C24 -> 1-轉生對照表 | D24: =計算表!D24 -> 轉生 7 次 | E24: =計算表!E24 -> （查表） | F24: a=生命與四維最終倍率 b=升級經驗倍率 c=升級經驗基礎增加值 d=階級名稱 e=潛力技能等級上限（查表）。 f=已停用（舊融合技上限增加值，2026-09-29 移除）。 | G24: =計算表!G24 -> 14 | H24: =計算表!H24 -> 10^7 | I24: =計算表!I24 -> 48000000 | J24: =計算表!J24 -> 神聖尊者 | K24: =計算表!K24 -> 24 | L24: =計算表!L24 -> 0 | M24: =計算表!M24 -> 0 | N24: =計算表!N24 -> 0 | ... R24: =計算表!R24 -> 0
A25: =計算表!A25 -> 24 | B25: =計算表!B25 -> 0 | C25: =計算表!C25 -> 1-轉生對照表 | D25: =計算表!D25 -> 轉生 8 次 | E25: =計算表!E25 -> （查表） | F25: a=生命與四維最終倍率 b=升級經驗倍率 c=升級經驗基礎增加值 d=階級名稱 e=潛力技能等級上限（查表）。 f=已停用（舊融合技上限增加值，2026-09-29 移除）。 | G25: =計算表!G25 -> 18 | H25: =計算表!H25 -> 10^8 | I25: =計算表!I25 -> 96000000 | J25: =計算表!J25 -> 大聖王 | K25: =計算表!K25 -> 26 | L25: =計算表!L25 -> 0 | M25: =計算表!M25 -> 0 | N25: =計算表!N25 -> 0 | ... R25: =計算表!R25 -> 0
A26: =計算表!A26 -> 25 | B26: =計算表!B26 -> 0 | C26: =計算表!C26 -> 1-轉生對照表 | D26: =計算表!D26 -> 轉生 9 次 | E26: =計算表!E26 -> （查表） | F26: a=生命與四維最終倍率 b=升級經驗倍率 c=升級經驗基礎增加值 d=階級名稱 e=潛力技能等級上限（查表）。 f=已停用（舊融合技上限增加值，2026-09-29 移除）。 | G26: =計算表!G26 -> 24 | H26: =計算表!H26 -> 10^9 | I26: =計算表!I26 -> 192000000 | J26: =計算表!J26 -> 至高主宰 | K26: =計算表!K26 -> 28 | L26: =計算表!L26 -> 0 | M26: =計算表!M26 -> 0 | N26: =計算表!N26 -> 0 | ... R26: =計算表!R26 -> 0
A27: =計算表!A27 -> 26 | B27: =計算表!B27 -> 0 | C27: =計算表!C27 -> 1-轉生對照表 | D27: =計算表!D27 -> 轉生 10 次 | E27: =計算表!E27 -> （查表） | F27: a=生命與四維最終倍率 b=升級經驗倍率 c=升級經驗基礎增加值 d=階級名稱 e=潛力技能等級上限（查表）。 f=已停用（舊融合技上限增加值，2026-09-29 移除）。 | G27: =計算表!G27 -> 30 | H27: =計算表!H27 -> 10^11 | I27: =計算表!I27 -> 384000000 | J27: =計算表!J27 -> 位面創世神 | K27: =計算表!K27 -> 30 | L27: =計算表!L27 -> 0 | M27: =計算表!M27 -> 0 | N27: =計算表!N27 -> 0 | ... R27: =計算表!R27 -> 0
A28: =計算表!A28 -> 27 | B28: =計算表!B28 -> 0 | C28: =計算表!C28 -> 1-轉生對照表 | D28: =計算表!D28 -> 轉生 11 次 | E28: =計算表!E28 -> （查表） | F28: a=生命與四維最終倍率 b=升級經驗倍率 c=升級經驗基礎增加值 d=階級名稱 e=潛力技能等級上限（查表）。 f=已停用（舊融合技上限增加值，2026-09-29 移除）。 | G28: =計算表!G28 -> 60 | H28: =計算表!H28 -> 10^13 | I28: =計算表!I28 -> 768000000 | J28: =計算表!J28 -> 神位1階 | K28: =計算表!K28 -> 30 | L28: =計算表!L28 -> 0 | M28: =計算表!M28 -> 0 | N28: =計算表!N28 -> 0 | ... R28: =計算表!R28 -> 0
... A37: =計算表!A37 -> 36 | B37: =計算表!B37 -> 0 | C37: =計算表!C37 -> 1-轉生對照表 | D37: =計算表!D37 -> 轉生 20 次 | E37: =計算表!E37 -> （查表） | F37: a=生命與四維最終倍率 b=升級經驗倍率 c=升級經驗基礎增加值 d=階級名稱 e=潛力技能等級上限（查表）。 f=已停用（舊融合技上限增加值，2026-09-29 移除）。 | G37: =計算表!G37 -> 2500 | H37: =計算表!H37 -> 10^33 | I37: =計算表!I37 -> 393216000000 | J37: =計算表!J37 -> 神位終階 | K37: =計算表!K37 -> 30 | L37: =計算表!L37 -> 0 | M37: =計算表!M37 -> 0 | N37: =計算表!N37 -> 0 | ... R37: =計算表!R37 -> 0
A38: =計算表!A38 -> 37 | B38: =計算表!B38 -> 0 | C38: =計算表!C38 -> 2-屬性上限 | D38: =計算表!D38 -> 暴擊率 上限 | E38: =計算表!E38 -> 上限 = a | F38: =計算表!F38 -> a=暴擊率上限（%）。攻擊時造成額外暴擊傷害的機率。 | G38: =計算表!G38 -> 0 | H38: =計算表!H38 -> 0 | ... R38: =計算表!R38 -> 0
A39: =計算表!A39 -> 38 | B39: =計算表!B39 -> 0 | C39: =計算表!C39 -> 2-屬性上限 | D39: =計算表!D39 -> 物理穿透 上限 | E39: =計算表!E39 -> 上限 = a | F39: =計算表!F39 -> a=物理穿透上限（%）；0＝無上限。2026-07-30 改版：穿透不再擋上限，實際忽略防禦%改由「3-戰鬥核心/穿透忽略防禦」的遞減曲線換算。 | G39: =計算表!G39 -> 0 | H39: =計算表!H39 -> 0 | ... R39: =計算表!R39 -> 0
A40: =計算表!A40 -> 39 | B40: =計算表!B40 -> 0 | C40: =計算表!C40 -> 2-屬性上限 | D40: =計算表!D40 -> 魔法穿透 上限 | E40: =計算表!E40 -> 上限 = a | F40: =計算表!F40 -> a=魔法穿透上限（%）；0＝無上限。2026-07-30 改版：穿透不再擋上限，實際忽略防禦%改由「3-戰鬥核心/穿透忽略防禦」的遞減曲線換算。 | G40: =計算表!G40 -> 0 | H40: =計算表!H40 -> 0 | ... R40: =計算表!R40 -> 0
A41: =計算表!A41 -> 40 | B41: =計算表!B41 -> 0 | C41: =計算表!C41 -> 2-屬性上限 | D41: =計算表!D41 -> 冷卻縮減 上限 | E41: =計算表!E41 -> 上限 = a | F41: =計算表!F41 -> a=冷卻縮減上限（%）。減少技能所需的冷卻時間。 | G41: =計算表!G41 -> 60 | H41: =計算表!H41 -> 0 | ... R41: =計算表!R41 -> 0
A42: =計算表!A42 -> 41 | B42: =計算表!B42 -> 0 | C42: =計算表!C42 -> 2-屬性上限 | D42: =計算表!D42 -> 施法速度 上限 | E42: =計算表!E42 -> 上限 = a | F42: =計算表!F42 -> a=施法速度上限（%）。縮短技能的施放延遲或詠唱時間。 | G42: =計算表!G42 -> 50 | H42: =計算表!H42 -> 0 | ... R42: =計算表!R42 -> 0
A43: =計算表!A43 -> 42 | B43: =計算表!B43 -> 0 | C43: =計算表!C43 -> 2-屬性上限 | D43: =計算表!D43 -> 吸血 上限 | E43: =計算表!E43 -> 上限 = a | F43: =計算表!F43 -> a=吸血上限（定值）；0＝無上限。吸血是定值：每次對敵人造成傷害固定回復的生命（舊版百分比以 1%＝1 轉換），單獨計算，與每秒生命回復、造成的傷害皆無關。 | G43: =計算表!G43 -> 0 | H43: =計算表!H43 -> 0 | ... R43: =計算表!R43 -> 0
A44: =計算表!A44 -> 43 | B44: =計算表!B44 -> 0 | C44: =計算表!C44 -> 2-屬性上限 | D44: =計算表!D44 -> 吸魔 上限 | E44: =計算表!E44 -> 上限 = a | F44: =計算表!F44 -> a=吸魔上限（定值）；0＝無上限。吸魔是定值：每次對敵人造成傷害固定回復的法力（舊版百分比以 1%＝1 轉換），單獨計算，與每秒法力恢復、造成的傷害皆無關。 | G44: =計算表!G44 -> 0 | H44: =計算表!H44 -> 0 | ... R44: =計算表!R44 -> 0
A45: =計算表!A45 -> 44 | B45: =計算表!B45 -> 0 | C45: =計算表!C45 -> 2-屬性上限 | D45: =計算表!D45 -> 格擋率 上限 | E45: =計算表!E45 -> 上限 = a | F45: =計算表!F45 -> a=格擋率上限（%）。受到攻擊時觸發格擋以減輕傷害的機率。 | G45: =計算表!G45 -> 50 | H45: =計算表!H45 -> 0 | ... R45: =計算表!R45 -> 0
A46: =計算表!A46 -> 45 | B46: =計算表!B46 -> 0 | C46: =計算表!C46 -> 2-屬性上限 | D46: =計算表!D46 -> 格擋減傷(詞條部分) 上限 | E46: =計算表!E46 -> 上限 = a | F46: =計算表!F46 -> a=格擋減傷「詞條部分」上限（%）。實際格擋減傷 = 30%基礎 + 詞條(≤a)，合計上限 80%。 | G46: =計算表!G46 -> 50 | H46: =計算表!H46 -> 0 | ... R46: =計算表!R46 -> 0
A47: =計算表!A47 -> 46 | B47: =計算表!B47 -> 0 | C47: =計算表!C47 -> 2-屬性上限 | D47: =計算表!D47 -> 閃避率 上限 | E47: =計算表!E47 -> 上限 = a | F47: =計算表!F47 -> a=閃避率上限（%）。完全避開敵人攻擊的機率（受敵方命中率影響）。 | G47: =計算表!G47 -> 0 | H47: =計算表!H47 -> 0 | ... R47: =計算表!R47 -> 0
A48: =計算表!A48 -> 47 | B48: =計算表!B48 -> 0 | C48: =計算表!C48 -> 2-屬性上限 | D48: =計算表!D48 -> 韌性 上限 | E48: =計算表!E48 -> 上限 = a | F48: =計算表!F48 -> a=韌性上限（%）。2026-07-30 改版：上限 80%，且同時降低「被控場機率」、縮短「被控場持續時間」、降低「被敵人爆擊機率」（敵方爆擊率×(1-韌性%)）。 | G48: =計算表!G48 -> 80 | H48: =計算表!H48 -> 0 | ... R48: =計算表!R48 -> 0
...

Sheet 計算表
A1: 編號 | B1: 變動 | C1: 系統分類 | D1: 名稱 | E1: 參數化公式 | F1: 中文說明 | G1: 參數a | H1: 參數b | I1: 參數c | J1: 參數d | K1: 參數e | L1: 參數f | M1: 參數g | N1: 參數h | O1: 參數i | P1: 參數j | Q1: 參數k | R1: 參數l
A2: 1 | B2: 0 | C2: 0-遊戲預設 | D2: 開場金幣 | E2: a | F2: 新遊戲與重新開局時給予的金幣數量。 | G2: 50000 | H2: 0 | I2: 0 | J2: 0 | K2: 0 | L2: 0 | M2: 0 | N2: 0 | O2: 0 | P2: 0 | Q2: 0 | R2: 0
A3: =A2+1 -> 2 | B3: 0 | C3: 0-遊戲預設 | D3: 開場裝備碎片 | E3: a | F3: 新遊戲與重新開局時給予的裝備碎片數量。 | G3: 500 | H3: 0 | I3: 0 | J3: 0 | K3: 0 | L3: 0 | M3: 0 | N3: 0 | O3: 0 | P3: 0 | Q3: 0 | R3: 0
A4: =A3+1 -> 3 | B4: 0 | C4: 0-遊戲預設 | D4: 開場附魔精華 | E4: a | F4: 新遊戲與重新開局時給予的附魔精華數量。 | G4: 100 | H4: 0 | I4: 0 | J4: 0 | K4: 0 | L4: 0 | M4: 0 | N4: 0 | O4: 0 | P4: 0 | Q4: 0 | R4: 0
A5: =A4+1 -> 4 | B5: 0 | C5: 10-離線 | D5: 有效離線時間 | E5: min(實際離線秒數, a 小時) | F5: 1 分鐘內不計。 | G5: 24 | H5: 0 | I5: 0 | J5: 0 | K5: 0 | L5: 0 | M5: 0 | N5: 0 | O5: 0 | P5: 0 | Q5: 0 | R5: 0
A6: =A5+1 -> 5 | B6: 0 | C6: 10-離線 | D6: 計算等級 | E6: 捨去((目前地圖最高階段 × c - a) ÷ b) × b（下限 1） | F6: a=等級扣減；b=取整單位；c=關卡比例；以此等級的當前場景菁英怪計算離線收益。 | G6: 10 | H6: 10 | I6: 1 | J6: 0 | K6: 0 | L6: 0 | M6: 0 | N6: 0 | O6: 0 | P6: 0 | Q6: 0 | R6: 0
A7: =A6+1 -> 6 | B7: 0 | C7: 10-離線 | D7: 擊殺速率 | E7: 每 a 秒擊殺 1 隻菁英怪 | F7: a=擊殺間隔秒數；擊殺數 = ⌊有效離線秒數 ÷ a⌋，每隻菁英怪及其掉落單獨擲骰。 | G7: 10 | H7: 0 | I7: 0 | J7: 0 | K7: 0 | L7: 0 | M7: 0 | N7: 0 | O7: 0 | P7: 0 | Q7: 0 | R7: 0
A8: =A7+1 -> 7 | B8: 0 | C8: 10-離線 | D8: 怪物種類 | E8: a＝1 時使用菁英怪；a＝0 時使用普通怪 | F8: 離線收益的怪物種類；菁英怪會套用菁英經驗與掉落倍率。 | G8: 1 | H8: 0 | I8: 0 | J8: 0 | K8: 0 | L8: 0 | M8: 0 | N8: 0 | O8: 0 | P8: 0 | Q8: 0 | R8: 0
A9: =A8+1 -> 8 | B9: 0 | C9: 1-成長經驗 | D9: 升級所需經驗 | E9: (a×等級^b+c)×轉生經驗倍率+轉生經驗基礎增加值 | F9: 升到下一級所需經驗；a=係數 b=次方 c=常數 d=等級上限。轉生經驗倍率見「轉生對照表」 | G9: 20 | H9: 3 | I9: 40 | J9: 1000 | K9: 0 | L9: 0 | M9: 0 | N9: 0 | O9: 0 | P9: 0 | Q9: 0 | R9: 0
A10: =A9+1 -> 9 | B10: 0 | C10: 1-成長經驗 | D10: 等級基礎四維 | E10: a+(等級-1)×b | F10: 力/敏/智/耐四項相同，每升 1 級各 +b。a=初始值 b=每級成長。 | G10: 5 | H10: 2 | I10: 0 | J10: 0 | K10: 0 | L10: 0 | M10: 0 | N10: 0 | O10: 0 | P10: 0 | Q10: 0 | R10: 0
A11: =A10+1 -> 10 | B11: 0 | C11: 1-成長經驗 | D11: 技能點總預算 | E11: 基礎a + 技能熟練度等級 + 潛力天賦加成 | F11: 2026-07-30 改制：技能點不再隨角色升級發放，改由技能熟練度提供（每級 1 點）。a=基礎點數（開局兩個 1 級技能）；b 停用；c=舊制上限常數（保留相容）。 | G11: 3 | H11: 1 | I11: 10000 | J11: 0 | K11: 0 | L11: 0 | M11: 0 | N11: 0 | O11: 0 | P11: 0 | Q11: 0 | R11: 0
A12: =A11+1 -> 11 | B12: 0 | C12: 1-成長經驗 | D12: 技能裝載欄 | E12: clamp(⌊等級/a⌋, b, c) | F12: 每 a 級 +1 格，最少 b、最多 c。 | G12: 50 | H12: 4 | I12: 6 | J12: 0 | K12: 0 | L12: 0 | M12: 0 | N12: 0 | O12: 0 | P12: 0 | Q12: 0 | R12: 0
A13: =A12+1 -> 12 | B13: 0 | C13: 1-成長經驗 | D13: 可轉生等級 / 最高轉生 | E13: 達到a級可轉生；最高b轉 | F13: a=可轉生等級 b=最高轉生次數。 | G13: 1000 | H13: 20 | I13: 0 | J13: 0 | K13: 0 | L13: 0 | M13: 0 | N13: 0 | O13: 0 | P13: 0 | Q13: 0 | R13: 0
A14: =A13+1 -> 13 | B14: 0 | C14: 1-成長經驗 | D14: 神鑄系統解鎖等級 | E14: b 轉達到a級開放 | F14: 解鎖後永久保留，轉生不關閉。a=解鎖等級 b=解鎖轉生等級，必需兩個條件都滿足才解鎖 | G14: 1 | H14: 1 | I14: 0 | J14: 0 | K14: 0 | L14: 0 | M14: 0 | N14: 0 | O14: 0 | P14: 0 | Q14: 0 | R14: 0
... A16: =A15+1 -> 15 | B16: 0 | C16: 1-成長經驗 | D16: 技能熟練度 | E16: 上限 a 級；擊殺技能經驗 = 怪物經驗 × b% | F16: 打怪（野外/高塔/離線）獲得技能經驗；每升 1 級 +1 技能點。初始 0 級。 | G16: 1000 | H16: 90 | I16: 0 | J16: 0 | K16: 0 | L16: 0 | M16: 0 | N16: 0 | O16: 0 | P16: 0 | Q16: 0 | R16: 0
A17: =A16+1 -> 16 | B17: 0 | C17: 1-轉生對照表 | D17: 轉生 0 次 | E17: （查表） | F17: a=生命與四維最終倍率 b=升級經驗倍率 c=升級經驗基礎增加值 d=階級名稱 e=全部技能等級上限（2026-07-30 改制：未轉生 10、轉生後 15；含被動/融合/潛力） f=融合技增加上限（改制後歸零，融合技與一般技能共用上限）。 | G17: 1 | H17: 10^0 | I17: 0 | J17: 冒險者 | K17: 10 | L17: 0 | M17: 0 | N17: 0 | O17: 0 | P17: 0 | Q17: 0 | R17: 0
A18: =A17+1 -> 17 | B18: 0 | C18: 1-轉生對照表 | D18: 轉生 1 次 | E18: （查表） | F18: a=生命與四維最終倍率 b=升級經驗倍率 c=升級經驗基礎增加值 d=階級名稱 e=全部技能等級上限（2026-07-30 改制：未轉生 10、轉生後 15；含被動/融合/潛力） f=融合技增加上限（改制後歸零，融合技與一般技能共用上限）。 | G18: 1.5 | H18: 10^1 | I18: 500000 | J18: 勇者 | K18: 12 | L18: 0 | M18: 0 | N18: 0 | O18: 0 | P18: 0 | Q18: 0 | R18: 0
A19: =A18+1 -> 18 | B19: 0 | C19: 1-轉生對照表 | D19: 轉生 2 次 | E19: （查表） | F19: a=生命與四維最終倍率 b=升級經驗倍率 c=升級經驗基礎增加值 d=階級名稱 e=全部技能等級上限（2026-07-30 改制：未轉生 10、轉生後 15；含被動/融合/潛力） f=融合技增加上限（改制後歸零，融合技與一般技能共用上限）。 | G19: 2.5 | H19: 10^2 | I19: 1500000 | J19: 大劍師 | K19: 14 | L19: 0 | M19: 0 | N19: 0 | O19: 0 | P19: 0 | Q19: 0 | R19: 0
A20: =A19+1 -> 19 | B20: 0 | C20: 1-轉生對照表 | D20: 轉生 3 次 | E20: （查表） | F20: a=生命與四維最終倍率 b=升級經驗倍率 c=升級經驗基礎增加值 d=階級名稱 e=全部技能等級上限（2026-07-30 改制：未轉生 10、轉生後 15；含被動/融合/潛力） f=融合技增加上限（改制後歸零，融合技與一般技能共用上限）。 | G20: 3.5 | H20: 10^3 | I20: 3000000 | J20: 破世者 | K20: 16 | L20: 0 | M20: 0 | N20: 0 | O20: 0 | P20: 0 | Q20: 0 | R20: 0
A21: =A20+1 -> 20 | B21: 0 | C21: 1-轉生對照表 | D21: 轉生 4 次 | E21: （查表） | F21: a=生命與四維最終倍率 b=升級經驗倍率 c=升級經驗基礎增加值 d=階級名稱 e=全部技能等級上限（2026-07-30 改制：未轉生 10、轉生後 15；含被動/融合/潛力） f=融合技增加上限（改制後歸零，融合技與一般技能共用上限）。 | G21: 5 | H21: 10^4 | I21: 6000000 | J21: 不朽者 | K21: 18 | L21: 0 | M21: 0 | N21: 0 | O21: 0 | P21: 0 | Q21: 0 | R21: 0
A22: =A21+1 -> 21 | B22: 0 | C22: 1-轉生對照表 | D22: 轉生 5 次 | E22: （查表） | F22: a=生命與四維最終倍率 b=升級經驗倍率 c=升級經驗基礎增加值 d=階級名稱 e=全部技能等級上限（2026-07-30 改制：未轉生 10、轉生後 15；含被動/融合/潛力） f=融合技增加上限（改制後歸零，融合技與一般技能共用上限）。 | G22: 7 | H22: 10^5 | I22: 12000000 | J22: 王者 | K22: 20 | L22: 0 | M22: 0 | N22: 0 | O22: 0 | P22: 0 | Q22: 0 | R22: 0
A23: =A22+1 -> 22 | B23: 0 | C23: 1-轉生對照表 | D23: 轉生 6 次 | E23: （查表） | F23: a=生命與四維最終倍率 b=升級經驗倍率 c=升級經驗基礎增加值 d=階級名稱 e=全部技能等級上限（2026-07-30 改制：未轉生 10、轉生後 15；含被動/融合/潛力） f=融合技增加上限（改制後歸零，融合技與一般技能共用上限）。 | G23: 10 | H23: 10^6 | I23: 24000000 | J23: 大主宰 | K23: 22 | L23: 0 | M23: 0 | N23: 0 | O23: 0 | P23: 0 | Q23: 0 | R23: 0
A24: =A23+1 -> 23 | B24: 0 | C24: 1-轉生對照表 | D24: 轉生 7 次 | E24: （查表） | F24: a=生命與四維最終倍率 b=升級經驗倍率 c=升級經驗基礎增加值 d=階級名稱 e=全部技能等級上限（2026-07-30 改制：未轉生 10、轉生後 15；含被動/融合/潛力） f=融合技增加上限（改制後歸零，融合技與一般技能共用上限）。 | G24: 14 | H24: 10^7 | I24: 48000000 | J24: 神聖尊者 | K24: 24 | L24: 0 | M24: 0 | N24: 0 | O24: 0 | P24: 0 | Q24: 0 | R24: 0
A25: =A24+1 -> 24 | B25: 0 | C25: 1-轉生對照表 | D25: 轉生 8 次 | E25: （查表） | F25: a=生命與四維最終倍率 b=升級經驗倍率 c=升級經驗基礎增加值 d=階級名稱 e=全部技能等級上限（2026-07-30 改制：未轉生 10、轉生後 15；含被動/融合/潛力） f=融合技增加上限（改制後歸零，融合技與一般技能共用上限）。 | G25: 18 | H25: 10^8 | I25: 96000000 | J25: 大聖王 | K25: 26 | L25: 0 | M25: 0 | N25: 0 | O25: 0 | P25: 0 | Q25: 0 | R25: 0
A26: =A25+1 -> 25 | B26: 0 | C26: 1-轉生對照表 | D26: 轉生 9 次 | E26: （查表） | F26: a=生命與四維最終倍率 b=升級經驗倍率 c=升級經驗基礎增加值 d=階級名稱 e=全部技能等級上限（2026-07-30 改制：未轉生 10、轉生後 15；含被動/融合/潛力） f=融合技增加上限（改制後歸零，融合技與一般技能共用上限）。 | G26: 24 | H26: 10^9 | I26: 192000000 | J26: 至高主宰 | K26: 28 | L26: 0 | M26: 0 | N26: 0 | O26: 0 | P26: 0 | Q26: 0 | R26: 0
A27: =A26+1 -> 26 | B27: 0 | C27: 1-轉生對照表 | D27: 轉生 10 次 | E27: （查表） | F27: a=生命與四維最終倍率 b=升級經驗倍率 c=升級經驗基礎增加值 d=階級名稱 e=全部技能等級上限（2026-07-30 改制：未轉生 10、轉生後 15；含被動/融合/潛力） f=融合技增加上限（改制後歸零，融合技與一般技能共用上限）。 | G27: 30 | H27: 10^11 | I27: 384000000 | J27: 位面創世神 | K27: 30 | L27: 0 | M27: 0 | N27: 0 | O27: 0 | P27: 0 | Q27: 0 | R27: 0
A28: =A27+1 -> 27 | B28: 0 | C28: 1-轉生對照表 | D28: 轉生 11 次 | E28: （查表） | F28: a=生命與四維最終倍率 b=升級經驗倍率 c=升級經驗基礎增加值 d=階級名稱 e=全部技能等級上限（2026-07-30 改制：未轉生 10、轉生後 15；含被動/融合/潛力） f=融合技增加上限（改制後歸零，融合技與一般技能共用上限）。 | G28: 60 | H28: 10^13 | I28: 768000000 | J28: 神位1階 | K28: 30 | L28: 0 | M28: 0 | N28: 0 | O28: 0 | P28: 0 | Q28: 0 | R28: 0
... A37: =A36+1 -> 36 | B37: 0 | C37: 1-轉生對照表 | D37: 轉生 20 次 | E37: （查表） | F37: a=生命與四維最終倍率 b=升級經驗倍率 c=升級經驗基礎增加值 d=階級名稱 e=全部技能等級上限（2026-07-30 改制：未轉生 10、轉生後 15；含被動/融合/潛力） f=融合技增加上限（改制後歸零，融合技與一般技能共用上限）。 | G37: 2500 | H37: 10^33 | I37: 393216000000 | J37: 神位終階 | K37: 30 | L37: 0 | M37: 0 | N37: 0 | O37: 0 | P37: 0 | Q37: 0 | R37: 0
A38: =A37+1 -> 37 | B38: 0 | C38: 2-屬性上限 | D38: 暴擊率 上限 | E38: 上限 = a | F38: a=暴擊率上限（%）。攻擊時造成額外暴擊傷害的機率。 | G38: 0 | H38: 0 | I38: 0 | J38: 0 | K38: 0 | L38: 0 | M38: 0 | N38: 0 | O38: 0 | P38: 0 | Q38: 0 | R38: 0
A39: =A38+1 -> 38 | B39: 0 | C39: 2-屬性上限 | D39: 物理穿透 上限 | E39: 上限 = a | F39: a=物理穿透上限（%）；0＝無上限。2026-07-30 改版：穿透不再擋上限，實際忽略防禦%改由「3-戰鬥核心/穿透忽略防禦」的遞減曲線換算。 | G39: 0 | H39: 0 | I39: 0 | J39: 0 | K39: 0 | L39: 0 | M39: 0 | N39: 0 | O39: 0 | P39: 0 | Q39: 0 | R39: 0
A40: =A39+1 -> 39 | B40: 0 | C40: 2-屬性上限 | D40: 魔法穿透 上限 | E40: 上限 = a | F40: a=魔法穿透上限（%）；0＝無上限。2026-07-30 改版：穿透不再擋上限，實際忽略防禦%改由「3-戰鬥核心/穿透忽略防禦」的遞減曲線換算。 | G40: 0 | H40: 0 | I40: 0 | J40: 0 | K40: 0 | L40: 0 | M40: 0 | N40: 0 | O40: 0 | P40: 0 | Q40: 0 | R40: 0
A41: =A40+1 -> 40 | B41: 0 | C41: 2-屬性上限 | D41: 冷卻縮減 上限 | E41: 上限 = a | F41: a=冷卻縮減上限（%）。減少技能所需的冷卻時間。 | G41: 60 | H41: 0 | I41: 0 | J41: 0 | K41: 0 | L41: 0 | M41: 0 | N41: 0 | O41: 0 | P41: 0 | Q41: 0 | R41: 0
A42: =A41+1 -> 41 | B42: 0 | C42: 2-屬性上限 | D42: 施法速度 上限 | E42: 上限 = a | F42: a=施法速度上限（%）。縮短技能的施放延遲或詠唱時間。 | G42: 50 | H42: 0 | I42: 0 | J42: 0 | K42: 0 | L42: 0 | M42: 0 | N42: 0 | O42: 0 | P42: 0 | Q42: 0 | R42: 0
A43: =A42+1 -> 42 | B43: 0 | C43: 2-屬性上限 | D43: 吸血 上限 | E43: 上限 = a | F43: a=吸血上限（定值）；0＝無上限。吸血是定值：每次對敵人造成傷害固定回復的生命（舊版百分比以 1%＝1 轉換），單獨計算，與每秒生命回復、造成的傷害皆無關。 | G43: 0 | H43: 0 | I43: 0 | J43: 0 | K43: 0 | L43: 0 | M43: 0 | N43: 0 | O43: 0 | P43: 0 | Q43: 0 | R43: 0
A44: =A43+1 -> 43 | B44: 0 | C44: 2-屬性上限 | D44: 吸魔 上限 | E44: 上限 = a | F44: a=吸魔上限（定值）；0＝無上限。吸魔是定值：每次對敵人造成傷害固定回復的法力（舊版百分比以 1%＝1 轉換），單獨計算，與每秒法力恢復、造成的傷害皆無關。 | G44: 0 | H44: 0 | I44: 0 | J44: 0 | K44: 0 | L44: 0 | M44: 0 | N44: 0 | O44: 0 | P44: 0 | Q44: 0 | R44: 0
A45: =A44+1 -> 44 | B45: 0 | C45: 2-屬性上限 | D45: 格擋率 上限 | E45: 上限 = a | F45: a=格擋率上限（%）。受到攻擊時觸發格擋以減輕傷害的機率。 | G45: 50 | H45: 0 | I45: 0 | J45: 0 | K45: 0 | L45: 0 | M45: 0 | N45: 0 | O45: 0 | P45: 0 | Q45: 0 | R45: 0
A46: =A45+1 -> 45 | B46: 0 | C46: 2-屬性上限 | D46: 格擋減傷(詞條部分) 上限 | E46: 上限 = a | F46: a=格擋減傷「詞條部分」上限（%）。實際格擋減傷 = 30%基礎 + 詞條(≤a)，合計上限 80%。 | G46: 50 | H46: 0 | I46: 0 | J46: 0 | K46: 0 | L46: 0 | M46: 0 | N46: 0 | O46: 0 | P46: 0 | Q46: 0 | R46: 0
A47: =A46+1 -> 46 | B47: 0 | C47: 2-屬性上限 | D47: 閃避率 上限 | E47: 上限 = a | F47: a=閃避率上限（%）。完全避開敵人攻擊的機率（受敵方命中率影響）。 | G47: 0 | H47: 0 | I47: 0 | J47: 0 | K47: 0 | L47: 0 | M47: 0 | N47: 0 | O47: 0 | P47: 0 | Q47: 0 | R47: 0
A48: =A47+1 -> 47 | B48: 0 | C48: 2-屬性上限 | D48: 韌性 上限 | E48: 上限 = a | F48: a=韌性上限（%）。2026-07-30 改版：上限 80%，且同時降低「被控場機率」、縮短「被控場持續時間」、降低「被敵人爆擊機率」（敵方爆擊率×(1-韌性%)）。 | G48: 80 | H48: 0 | I48: 0 | J48: 0 | K48: 0 | L48: 0 | M48: 0 | N48: 0 | O48: 0 | P48: 0 | Q48: 0 | R48: 0
A49: =A48+1 -> 48 | B49: 0 | C49: 2-屬性上限 | D49: 控制抵抗 上限 | E49: 上限 = a | F49: a=控制抵抗上限（%）。全面降低所有負面異常狀態的命中率。 | G49: 80 | H49: 0 | I49: 0 | J49: 0 | K49: 0 | L49: 0 | M49: 0 | N49: 0 | O49: 0 | P49: 0 | Q49: 0 | R49: 0
...
